[2025-02-23T10:28:04.677+0000] {local_task_job_runner.py:120} INFO - ::group::Pre task execution logs
[2025-02-23T10:28:04.709+0000] {taskinstance.py:2076} INFO - Dependencies all met for dep_context=non-requeueable deps ti=<TaskInstance: open_tax_etl.extract_task manual__2025-02-23T10:28:03.642667+00:00 [queued]>
[2025-02-23T10:28:04.725+0000] {taskinstance.py:2076} INFO - Dependencies all met for dep_context=requeueable deps ti=<TaskInstance: open_tax_etl.extract_task manual__2025-02-23T10:28:03.642667+00:00 [queued]>
[2025-02-23T10:28:04.726+0000] {taskinstance.py:2306} INFO - Starting attempt 1 of 1
[2025-02-23T10:28:04.735+0000] {taskinstance.py:2330} INFO - Executing <Task(PythonOperator): extract_task> on 2025-02-23 10:28:03.642667+00:00
[2025-02-23T10:28:04.744+0000] {standard_task_runner.py:90} INFO - Running: ['airflow', 'tasks', 'run', 'open_tax_etl', 'extract_task', 'manual__2025-02-23T10:28:03.642667+00:00', '--job-id', '10', '--raw', '--subdir', 'DAGS_FOLDER/opentaxetl.py', '--cfg-path', '/tmp/tmp939h47u0']
[2025-02-23T10:28:04.747+0000] {logging_mixin.py:188} WARNING - /home/airflow/.local/lib/python3.12/site-packages/airflow/task/task_runner/standard_task_runner.py:62 DeprecationWarning: This process (pid=398) is multi-threaded, use of fork() may lead to deadlocks in the child.
[2025-02-23T10:28:04.747+0000] {standard_task_runner.py:91} INFO - Job 10: Subtask extract_task
[2025-02-23T10:28:04.747+0000] {standard_task_runner.py:64} INFO - Started process 400 to run task
[2025-02-23T10:28:04.789+0000] {task_command.py:426} INFO - Running <TaskInstance: open_tax_etl.extract_task manual__2025-02-23T10:28:03.642667+00:00 [running]> on host 2cf524a0af0b
[2025-02-23T10:28:05.065+0000] {taskinstance.py:2648} INFO - Exporting env vars: AIRFLOW_CTX_DAG_OWNER='airflow' AIRFLOW_CTX_DAG_ID='open_tax_etl' AIRFLOW_CTX_TASK_ID='extract_task' AIRFLOW_CTX_EXECUTION_DATE='2025-02-23T10:28:03.642667+00:00' AIRFLOW_CTX_TRY_NUMBER='1' AIRFLOW_CTX_DAG_RUN_ID='manual__2025-02-23T10:28:03.642667+00:00'
[2025-02-23T10:28:05.065+0000] {taskinstance.py:430} INFO - ::endgroup::
[2025-02-23T10:28:05.095+0000] {taskinstance.py:441} INFO - ::group::Post task execution logs
[2025-02-23T10:28:05.095+0000] {taskinstance.py:2905} ERROR - Task failed with exception
Traceback (most recent call last):
  File "/home/airflow/.local/lib/python3.12/site-packages/airflow/models/taskinstance.py", line 465, in _execute_task
    result = _execute_callable(context=context, **execute_callable_kwargs)
             ^^^^^^^^^^^^^^^^^^^^^^^^^^^^^^^^^^^^^^^^^^^^^^^^^^^^^^^^^^^^^
  File "/home/airflow/.local/lib/python3.12/site-packages/airflow/models/taskinstance.py", line 432, in _execute_callable
    return execute_callable(context=context, **execute_callable_kwargs)
           ^^^^^^^^^^^^^^^^^^^^^^^^^^^^^^^^^^^^^^^^^^^^^^^^^^^^^^^^^^^^
  File "/home/airflow/.local/lib/python3.12/site-packages/airflow/models/baseoperator.py", line 401, in wrapper
    return func(self, *args, **kwargs)
           ^^^^^^^^^^^^^^^^^^^^^^^^^^^
  File "/home/airflow/.local/lib/python3.12/site-packages/airflow/operators/python.py", line 235, in execute
    return_value = self.execute_callable()
                   ^^^^^^^^^^^^^^^^^^^^^^^
  File "/home/airflow/.local/lib/python3.12/site-packages/airflow/operators/python.py", line 252, in execute_callable
    return self.python_callable(*self.op_args, **self.op_kwargs)
           ^^^^^^^^^^^^^^^^^^^^^^^^^^^^^^^^^^^^^^^^^^^^^^^^^^^^^
  File "/opt/airflow/dags/opentaxetl.py", line 14, in extract_transactional_data
    kwargs['ti'].xcom_push(key='extracted_data', value=transaction_data_dict)
                                                       ^^^^^^^^^^^^^^^^^^^^^
NameError: name 'transaction_data_dict' is not defined
[2025-02-23T10:28:05.105+0000] {taskinstance.py:1206} INFO - Marking task as FAILED. dag_id=open_tax_etl, task_id=extract_task, run_id=manual__2025-02-23T10:28:03.642667+00:00, execution_date=20250223T102803, start_date=20250223T102804, end_date=20250223T102805
[2025-02-23T10:28:05.111+0000] {standard_task_runner.py:110} ERROR - Failed to execute job 10 for task extract_task (name 'transaction_data_dict' is not defined; 400)
[2025-02-23T10:28:05.142+0000] {local_task_job_runner.py:243} INFO - Task exited with return code 1
[2025-02-23T10:28:05.157+0000] {taskinstance.py:3503} INFO - 0 downstream tasks scheduled from follow-on schedule check
[2025-02-23T10:28:05.158+0000] {local_task_job_runner.py:222} INFO - ::endgroup::
