[2025-02-23T10:24:18.516+0000] {local_task_job_runner.py:120} INFO - ::group::Pre task execution logs
[2025-02-23T10:24:18.539+0000] {taskinstance.py:2076} INFO - Dependencies all met for dep_context=non-requeueable deps ti=<TaskInstance: open_tax_etl.extract_task manual__2025-02-23T10:24:17.773493+00:00 [queued]>
[2025-02-23T10:24:18.544+0000] {taskinstance.py:2076} INFO - Dependencies all met for dep_context=requeueable deps ti=<TaskInstance: open_tax_etl.extract_task manual__2025-02-23T10:24:17.773493+00:00 [queued]>
[2025-02-23T10:24:18.545+0000] {taskinstance.py:2306} INFO - Starting attempt 1 of 1
[2025-02-23T10:24:18.552+0000] {taskinstance.py:2330} INFO - Executing <Task(PythonOperator): extract_task> on 2025-02-23 10:24:17.773493+00:00
[2025-02-23T10:24:18.561+0000] {logging_mixin.py:188} WARNING - /home/airflow/.local/lib/python3.12/site-packages/airflow/task/task_runner/standard_task_runner.py:62 DeprecationWarning: This process (pid=299) is multi-threaded, use of fork() may lead to deadlocks in the child.
[2025-02-23T10:24:18.559+0000] {standard_task_runner.py:90} INFO - Running: ['airflow', 'tasks', 'run', 'open_tax_etl', 'extract_task', 'manual__2025-02-23T10:24:17.773493+00:00', '--job-id', '7', '--raw', '--subdir', 'DAGS_FOLDER/opentaxetl.py', '--cfg-path', '/tmp/tmp1ck_ch6w']
[2025-02-23T10:24:18.562+0000] {standard_task_runner.py:91} INFO - Job 7: Subtask extract_task
[2025-02-23T10:24:18.562+0000] {standard_task_runner.py:64} INFO - Started process 301 to run task
[2025-02-23T10:24:18.609+0000] {task_command.py:426} INFO - Running <TaskInstance: open_tax_etl.extract_task manual__2025-02-23T10:24:17.773493+00:00 [running]> on host 2cf524a0af0b
[2025-02-23T10:24:18.861+0000] {taskinstance.py:2648} INFO - Exporting env vars: AIRFLOW_CTX_DAG_OWNER='airflow' AIRFLOW_CTX_DAG_ID='open_tax_etl' AIRFLOW_CTX_TASK_ID='extract_task' AIRFLOW_CTX_EXECUTION_DATE='2025-02-23T10:24:17.773493+00:00' AIRFLOW_CTX_TRY_NUMBER='1' AIRFLOW_CTX_DAG_RUN_ID='manual__2025-02-23T10:24:17.773493+00:00'
[2025-02-23T10:24:18.861+0000] {taskinstance.py:430} INFO - ::endgroup::
[2025-02-23T10:24:18.872+0000] {taskinstance.py:441} INFO - ::group::Post task execution logs
[2025-02-23T10:24:18.873+0000] {taskinstance.py:2905} ERROR - Task failed with exception
Traceback (most recent call last):
  File "/home/airflow/.local/lib/python3.12/site-packages/airflow/models/taskinstance.py", line 465, in _execute_task
    result = _execute_callable(context=context, **execute_callable_kwargs)
             ^^^^^^^^^^^^^^^^^^^^^^^^^^^^^^^^^^^^^^^^^^^^^^^^^^^^^^^^^^^^^
  File "/home/airflow/.local/lib/python3.12/site-packages/airflow/models/taskinstance.py", line 432, in _execute_callable
    return execute_callable(context=context, **execute_callable_kwargs)
           ^^^^^^^^^^^^^^^^^^^^^^^^^^^^^^^^^^^^^^^^^^^^^^^^^^^^^^^^^^^^
  File "/home/airflow/.local/lib/python3.12/site-packages/airflow/models/baseoperator.py", line 401, in wrapper
    return func(self, *args, **kwargs)
           ^^^^^^^^^^^^^^^^^^^^^^^^^^^
  File "/home/airflow/.local/lib/python3.12/site-packages/airflow/operators/python.py", line 235, in execute
    return_value = self.execute_callable()
                   ^^^^^^^^^^^^^^^^^^^^^^^
  File "/home/airflow/.local/lib/python3.12/site-packages/airflow/operators/python.py", line 252, in execute_callable
    return self.python_callable(*self.op_args, **self.op_kwargs)
           ^^^^^^^^^^^^^^^^^^^^^^^^^^^^^^^^^^^^^^^^^^^^^^^^^^^^^
  File "/opt/airflow/dags/opentaxetl.py", line 9, in extract_transactional_data
    df = pd.read_csv(csv_file_path)
         ^^^^^^^^^^^^^^^^^^^^^^^^^^
  File "/home/airflow/.local/lib/python3.12/site-packages/pandas/io/parsers/readers.py", line 948, in read_csv
    return _read(filepath_or_buffer, kwds)
           ^^^^^^^^^^^^^^^^^^^^^^^^^^^^^^^
  File "/home/airflow/.local/lib/python3.12/site-packages/pandas/io/parsers/readers.py", line 611, in _read
    parser = TextFileReader(filepath_or_buffer, **kwds)
             ^^^^^^^^^^^^^^^^^^^^^^^^^^^^^^^^^^^^^^^^^^
  File "/home/airflow/.local/lib/python3.12/site-packages/pandas/io/parsers/readers.py", line 1448, in __init__
    self._engine = self._make_engine(f, self.engine)
                   ^^^^^^^^^^^^^^^^^^^^^^^^^^^^^^^^^
  File "/home/airflow/.local/lib/python3.12/site-packages/pandas/io/parsers/readers.py", line 1705, in _make_engine
    self.handles = get_handle(
                   ^^^^^^^^^^^
  File "/home/airflow/.local/lib/python3.12/site-packages/pandas/io/common.py", line 863, in get_handle
    handle = open(
             ^^^^^
FileNotFoundError: [Errno 2] No such file or directory: '/data/financial_transactions.csv'
[2025-02-23T10:24:18.880+0000] {taskinstance.py:1206} INFO - Marking task as FAILED. dag_id=open_tax_etl, task_id=extract_task, run_id=manual__2025-02-23T10:24:17.773493+00:00, execution_date=20250223T102417, start_date=20250223T102418, end_date=20250223T102418
[2025-02-23T10:24:18.886+0000] {standard_task_runner.py:110} ERROR - Failed to execute job 7 for task extract_task ([Errno 2] No such file or directory: '/data/financial_transactions.csv'; 301)
[2025-02-23T10:24:18.915+0000] {local_task_job_runner.py:243} INFO - Task exited with return code 1
[2025-02-23T10:24:18.925+0000] {taskinstance.py:3503} INFO - 0 downstream tasks scheduled from follow-on schedule check
[2025-02-23T10:24:18.926+0000] {local_task_job_runner.py:222} INFO - ::endgroup::
