[2025-02-23T10:27:38.408+0000] {local_task_job_runner.py:120} INFO - ::group::Pre task execution logs
[2025-02-23T10:27:38.432+0000] {taskinstance.py:2076} INFO - Dependencies all met for dep_context=non-requeueable deps ti=<TaskInstance: open_tax_etl.extract_task manual__2025-02-23T10:27:37.626101+00:00 [queued]>
[2025-02-23T10:27:38.439+0000] {taskinstance.py:2076} INFO - Dependencies all met for dep_context=requeueable deps ti=<TaskInstance: open_tax_etl.extract_task manual__2025-02-23T10:27:37.626101+00:00 [queued]>
[2025-02-23T10:27:38.439+0000] {taskinstance.py:2306} INFO - Starting attempt 1 of 1
[2025-02-23T10:27:38.450+0000] {taskinstance.py:2330} INFO - Executing <Task(PythonOperator): extract_task> on 2025-02-23 10:27:37.626101+00:00
[2025-02-23T10:27:38.458+0000] {standard_task_runner.py:90} INFO - Running: ['airflow', 'tasks', 'run', 'open_tax_etl', 'extract_task', 'manual__2025-02-23T10:27:37.626101+00:00', '--job-id', '9', '--raw', '--subdir', 'DAGS_FOLDER/opentaxetl.py', '--cfg-path', '/tmp/tmprdbqww_x']
[2025-02-23T10:27:38.460+0000] {logging_mixin.py:188} WARNING - /home/airflow/.local/lib/python3.12/site-packages/airflow/task/task_runner/standard_task_runner.py:62 DeprecationWarning: This process (pid=383) is multi-threaded, use of fork() may lead to deadlocks in the child.
[2025-02-23T10:27:38.461+0000] {standard_task_runner.py:91} INFO - Job 9: Subtask extract_task
[2025-02-23T10:27:38.461+0000] {standard_task_runner.py:64} INFO - Started process 385 to run task
[2025-02-23T10:27:38.496+0000] {task_command.py:426} INFO - Running <TaskInstance: open_tax_etl.extract_task manual__2025-02-23T10:27:37.626101+00:00 [running]> on host 2cf524a0af0b
[2025-02-23T10:27:38.762+0000] {taskinstance.py:2648} INFO - Exporting env vars: AIRFLOW_CTX_DAG_OWNER='airflow' AIRFLOW_CTX_DAG_ID='open_tax_etl' AIRFLOW_CTX_TASK_ID='extract_task' AIRFLOW_CTX_EXECUTION_DATE='2025-02-23T10:27:37.626101+00:00' AIRFLOW_CTX_TRY_NUMBER='1' AIRFLOW_CTX_DAG_RUN_ID='manual__2025-02-23T10:27:37.626101+00:00'
[2025-02-23T10:27:38.763+0000] {taskinstance.py:430} INFO - ::endgroup::
[2025-02-23T10:27:38.773+0000] {taskinstance.py:441} INFO - ::group::Post task execution logs
[2025-02-23T10:27:38.773+0000] {taskinstance.py:2905} ERROR - Task failed with exception
Traceback (most recent call last):
  File "/home/airflow/.local/lib/python3.12/site-packages/airflow/models/taskinstance.py", line 465, in _execute_task
    result = _execute_callable(context=context, **execute_callable_kwargs)
             ^^^^^^^^^^^^^^^^^^^^^^^^^^^^^^^^^^^^^^^^^^^^^^^^^^^^^^^^^^^^^
  File "/home/airflow/.local/lib/python3.12/site-packages/airflow/models/taskinstance.py", line 432, in _execute_callable
    return execute_callable(context=context, **execute_callable_kwargs)
           ^^^^^^^^^^^^^^^^^^^^^^^^^^^^^^^^^^^^^^^^^^^^^^^^^^^^^^^^^^^^
  File "/home/airflow/.local/lib/python3.12/site-packages/airflow/models/baseoperator.py", line 401, in wrapper
    return func(self, *args, **kwargs)
           ^^^^^^^^^^^^^^^^^^^^^^^^^^^
  File "/home/airflow/.local/lib/python3.12/site-packages/airflow/operators/python.py", line 235, in execute
    return_value = self.execute_callable()
                   ^^^^^^^^^^^^^^^^^^^^^^^
  File "/home/airflow/.local/lib/python3.12/site-packages/airflow/operators/python.py", line 252, in execute_callable
    return self.python_callable(*self.op_args, **self.op_kwargs)
           ^^^^^^^^^^^^^^^^^^^^^^^^^^^^^^^^^^^^^^^^^^^^^^^^^^^^^
  File "/opt/airflow/dags/opentaxetl.py", line 9, in extract_transactional_data
    csv_file_path = 'dags/data/financial_transactions.csv'
         ^^^^^^^^^^^^^^^^^^^^^^^^^^
  File "/home/airflow/.local/lib/python3.12/site-packages/pandas/io/parsers/readers.py", line 948, in read_csv
    return _read(filepath_or_buffer, kwds)
           ^^^^^^^^^^^^^^^^^^^^^^^^^^^^^^^
  File "/home/airflow/.local/lib/python3.12/site-packages/pandas/io/parsers/readers.py", line 611, in _read
    parser = TextFileReader(filepath_or_buffer, **kwds)
             ^^^^^^^^^^^^^^^^^^^^^^^^^^^^^^^^^^^^^^^^^^
  File "/home/airflow/.local/lib/python3.12/site-packages/pandas/io/parsers/readers.py", line 1448, in __init__
    self._engine = self._make_engine(f, self.engine)
                   ^^^^^^^^^^^^^^^^^^^^^^^^^^^^^^^^^
  File "/home/airflow/.local/lib/python3.12/site-packages/pandas/io/parsers/readers.py", line 1705, in _make_engine
    self.handles = get_handle(
                   ^^^^^^^^^^^
  File "/home/airflow/.local/lib/python3.12/site-packages/pandas/io/common.py", line 863, in get_handle
    handle = open(
             ^^^^^
FileNotFoundError: [Errno 2] No such file or directory: 'data/financial_transactions.csv'
[2025-02-23T10:27:38.781+0000] {taskinstance.py:1206} INFO - Marking task as FAILED. dag_id=open_tax_etl, task_id=extract_task, run_id=manual__2025-02-23T10:27:37.626101+00:00, execution_date=20250223T102737, start_date=20250223T102738, end_date=20250223T102738
[2025-02-23T10:27:38.787+0000] {standard_task_runner.py:110} ERROR - Failed to execute job 9 for task extract_task ([Errno 2] No such file or directory: 'data/financial_transactions.csv'; 385)
[2025-02-23T10:27:38.811+0000] {local_task_job_runner.py:243} INFO - Task exited with return code 1
[2025-02-23T10:27:38.824+0000] {taskinstance.py:3503} INFO - 0 downstream tasks scheduled from follow-on schedule check
[2025-02-23T10:27:38.825+0000] {local_task_job_runner.py:222} INFO - ::endgroup::
