[2025-02-23T10:22:28.578+0000] {local_task_job_runner.py:120} INFO - ::group::Pre task execution logs
[2025-02-23T10:22:28.604+0000] {taskinstance.py:2076} INFO - Dependencies all met for dep_context=non-requeueable deps ti=<TaskInstance: open_tax_etl.extract_task scheduled__2023-01-01T00:00:00+00:00 [queued]>
[2025-02-23T10:22:28.611+0000] {taskinstance.py:2076} INFO - Dependencies all met for dep_context=requeueable deps ti=<TaskInstance: open_tax_etl.extract_task scheduled__2023-01-01T00:00:00+00:00 [queued]>
[2025-02-23T10:22:28.613+0000] {taskinstance.py:2306} INFO - Starting attempt 1 of 1
[2025-02-23T10:22:28.623+0000] {taskinstance.py:2330} INFO - Executing <Task(PythonOperator): extract_task> on 2023-01-01 00:00:00+00:00
[2025-02-23T10:22:28.631+0000] {standard_task_runner.py:90} INFO - Running: ['airflow', 'tasks', 'run', 'open_tax_etl', 'extract_task', 'scheduled__2023-01-01T00:00:00+00:00', '--job-id', '5', '--raw', '--subdir', 'DAGS_FOLDER/opentaxetl.py', '--cfg-path', '/tmp/tmp5hb62ct7']
[2025-02-23T10:22:28.634+0000] {standard_task_runner.py:91} INFO - Job 5: Subtask extract_task
[2025-02-23T10:22:28.634+0000] {logging_mixin.py:188} WARNING - /home/airflow/.local/lib/python3.12/site-packages/airflow/task/task_runner/standard_task_runner.py:62 DeprecationWarning: This process (pid=252) is multi-threaded, use of fork() may lead to deadlocks in the child.
[2025-02-23T10:22:28.635+0000] {standard_task_runner.py:64} INFO - Started process 255 to run task
[2025-02-23T10:22:28.683+0000] {task_command.py:426} INFO - Running <TaskInstance: open_tax_etl.extract_task scheduled__2023-01-01T00:00:00+00:00 [running]> on host 2cf524a0af0b
[2025-02-23T10:22:28.980+0000] {taskinstance.py:2648} INFO - Exporting env vars: AIRFLOW_CTX_DAG_OWNER='airflow' AIRFLOW_CTX_DAG_ID='open_tax_etl' AIRFLOW_CTX_TASK_ID='extract_task' AIRFLOW_CTX_EXECUTION_DATE='2023-01-01T00:00:00+00:00' AIRFLOW_CTX_TRY_NUMBER='1' AIRFLOW_CTX_DAG_RUN_ID='scheduled__2023-01-01T00:00:00+00:00'
[2025-02-23T10:22:28.981+0000] {taskinstance.py:430} INFO - ::endgroup::
[2025-02-23T10:22:29.009+0000] {taskinstance.py:441} INFO - ::group::Post task execution logs
[2025-02-23T10:22:29.010+0000] {taskinstance.py:2905} ERROR - Task failed with exception
Traceback (most recent call last):
  File "/home/airflow/.local/lib/python3.12/site-packages/airflow/models/taskinstance.py", line 465, in _execute_task
    result = _execute_callable(context=context, **execute_callable_kwargs)
             ^^^^^^^^^^^^^^^^^^^^^^^^^^^^^^^^^^^^^^^^^^^^^^^^^^^^^^^^^^^^^
  File "/home/airflow/.local/lib/python3.12/site-packages/airflow/models/taskinstance.py", line 432, in _execute_callable
    return execute_callable(context=context, **execute_callable_kwargs)
           ^^^^^^^^^^^^^^^^^^^^^^^^^^^^^^^^^^^^^^^^^^^^^^^^^^^^^^^^^^^^
  File "/home/airflow/.local/lib/python3.12/site-packages/airflow/models/baseoperator.py", line 401, in wrapper
    return func(self, *args, **kwargs)
           ^^^^^^^^^^^^^^^^^^^^^^^^^^^
  File "/home/airflow/.local/lib/python3.12/site-packages/airflow/operators/python.py", line 235, in execute
    return_value = self.execute_callable()
                   ^^^^^^^^^^^^^^^^^^^^^^^
  File "/home/airflow/.local/lib/python3.12/site-packages/airflow/operators/python.py", line 252, in execute_callable
    return self.python_callable(*self.op_args, **self.op_kwargs)
           ^^^^^^^^^^^^^^^^^^^^^^^^^^^^^^^^^^^^^^^^^^^^^^^^^^^^^
  File "/opt/airflow/dags/opentaxetl.py", line 9, in extract_transactional_data
    df = pd.read_csv(csv_file_path)
         ^^^^^^^^^^^^^^^^^^^^^^^^^^
  File "/home/airflow/.local/lib/python3.12/site-packages/pandas/io/parsers/readers.py", line 948, in read_csv
    return _read(filepath_or_buffer, kwds)
           ^^^^^^^^^^^^^^^^^^^^^^^^^^^^^^^
  File "/home/airflow/.local/lib/python3.12/site-packages/pandas/io/parsers/readers.py", line 611, in _read
    parser = TextFileReader(filepath_or_buffer, **kwds)
             ^^^^^^^^^^^^^^^^^^^^^^^^^^^^^^^^^^^^^^^^^^
  File "/home/airflow/.local/lib/python3.12/site-packages/pandas/io/parsers/readers.py", line 1448, in __init__
    self._engine = self._make_engine(f, self.engine)
                   ^^^^^^^^^^^^^^^^^^^^^^^^^^^^^^^^^
  File "/home/airflow/.local/lib/python3.12/site-packages/pandas/io/parsers/readers.py", line 1705, in _make_engine
    self.handles = get_handle(
                   ^^^^^^^^^^^
  File "/home/airflow/.local/lib/python3.12/site-packages/pandas/io/common.py", line 863, in get_handle
    handle = open(
             ^^^^^
FileNotFoundError: [Errno 2] No such file or directory: '/data/financial_transactions.csv'
[2025-02-23T10:22:29.024+0000] {taskinstance.py:1206} INFO - Marking task as FAILED. dag_id=open_tax_etl, task_id=extract_task, run_id=scheduled__2023-01-01T00:00:00+00:00, execution_date=20230101T000000, start_date=20250223T102228, end_date=20250223T102229
[2025-02-23T10:22:29.034+0000] {standard_task_runner.py:110} ERROR - Failed to execute job 5 for task extract_task ([Errno 2] No such file or directory: '/data/financial_transactions.csv'; 255)
[2025-02-23T10:22:29.064+0000] {local_task_job_runner.py:243} INFO - Task exited with return code 1
[2025-02-23T10:22:29.081+0000] {taskinstance.py:3503} INFO - 0 downstream tasks scheduled from follow-on schedule check
[2025-02-23T10:22:29.083+0000] {local_task_job_runner.py:222} INFO - ::endgroup::
[2025-02-24T07:28:42.504+0000] {local_task_job_runner.py:120} INFO - ::group::Pre task execution logs
[2025-02-24T07:28:42.695+0000] {taskinstance.py:2076} INFO - Dependencies all met for dep_context=non-requeueable deps ti=<TaskInstance: open_tax_etl.extract_task scheduled__2023-01-01T00:00:00+00:00 [queued]>
[2025-02-24T07:28:42.720+0000] {taskinstance.py:2076} INFO - Dependencies all met for dep_context=requeueable deps ti=<TaskInstance: open_tax_etl.extract_task scheduled__2023-01-01T00:00:00+00:00 [queued]>
[2025-02-24T07:28:42.721+0000] {taskinstance.py:2306} INFO - Starting attempt 1 of 1
[2025-02-24T07:28:42.774+0000] {taskinstance.py:2330} INFO - Executing <Task(PythonOperator): extract_task> on 2023-01-01 00:00:00+00:00
[2025-02-24T07:28:42.861+0000] {standard_task_runner.py:90} INFO - Running: ['airflow', 'tasks', 'run', 'open_tax_etl', 'extract_task', 'scheduled__2023-01-01T00:00:00+00:00', '--job-id', '3', '--raw', '--subdir', 'DAGS_FOLDER/opentaxetl.py', '--cfg-path', '/tmp/tmpq6qvhe08']
[2025-02-24T07:28:42.876+0000] {standard_task_runner.py:91} INFO - Job 3: Subtask extract_task
[2025-02-24T07:28:42.992+0000] {logging_mixin.py:188} WARNING - /home/airflow/.local/lib/python3.12/site-packages/airflow/task/task_runner/standard_task_runner.py:62 DeprecationWarning: This process (pid=284) is multi-threaded, use of fork() may lead to deadlocks in the child.
[2025-02-24T07:28:43.015+0000] {standard_task_runner.py:64} INFO - Started process 288 to run task
[2025-02-24T07:28:43.326+0000] {task_command.py:426} INFO - Running <TaskInstance: open_tax_etl.extract_task scheduled__2023-01-01T00:00:00+00:00 [running]> on host a44c47f48a9b
[2025-02-24T07:28:44.297+0000] {taskinstance.py:2648} INFO - Exporting env vars: AIRFLOW_CTX_DAG_OWNER='airflow' AIRFLOW_CTX_DAG_ID='open_tax_etl' AIRFLOW_CTX_TASK_ID='extract_task' AIRFLOW_CTX_EXECUTION_DATE='2023-01-01T00:00:00+00:00' AIRFLOW_CTX_TRY_NUMBER='1' AIRFLOW_CTX_DAG_RUN_ID='scheduled__2023-01-01T00:00:00+00:00'
[2025-02-24T07:28:44.316+0000] {taskinstance.py:430} INFO - ::endgroup::
[2025-02-24T07:28:48.901+0000] {opentaxetl.py:35} INFO - Beginning to extract data from source
[2025-02-24T07:28:49.283+0000] {taskinstance.py:441} INFO - ::group::Post task execution logs
[2025-02-24T07:28:49.358+0000] {taskinstance.py:2905} ERROR - Task failed with exception
Traceback (most recent call last):
  File "/opt/airflow/dags/opentaxetl.py", line 47, in extract_transactional_data
    audit_logs(dag_id,task_id,'INFO','Succesfully Extracted Data from CSV')
  File "/opt/airflow/dags/pipeline_logs.py", line 14, in audit_logs
    postgres_hook_engine = PostgresHook(postgres_conn_id='opentax_postgres_conn').get_sqlalchemy_engine()
                           ^^^^^^^^^^^^^^^^^^^^^^^^^^^^^^^^^^^^^^^^^^^^^^^^^^^^^^^^^^^^^^^^^^^^^^^^^^^^^^
  File "/home/airflow/.local/lib/python3.12/site-packages/airflow/providers/common/sql/hooks/sql.py", line 245, in get_sqlalchemy_engine
    return create_engine(self.get_uri(), **engine_kwargs)
                         ^^^^^^^^^^^^^^
  File "/home/airflow/.local/lib/python3.12/site-packages/airflow/providers/postgres/hooks/postgres.py", line 204, in get_uri
    return self.sqlalchemy_url.render_as_string(hide_password=False)
           ^^^^^^^^^^^^^^^^^^^
  File "/home/airflow/.local/lib/python3.12/site-packages/airflow/providers/postgres/hooks/postgres.py", line 119, in sqlalchemy_url
    conn = self.get_connection(getattr(self, self.conn_name_attr))
           ^^^^^^^^^^^^^^^^^^^^^^^^^^^^^^^^^^^^^^^^^^^^^^^^^^^^^^^
  File "/home/airflow/.local/lib/python3.12/site-packages/airflow/hooks/base.py", line 83, in get_connection
    conn = Connection.get_connection_from_secrets(conn_id)
           ^^^^^^^^^^^^^^^^^^^^^^^^^^^^^^^^^^^^^^^^^^^^^^^
  File "/home/airflow/.local/lib/python3.12/site-packages/airflow/models/connection.py", line 519, in get_connection_from_secrets
    raise AirflowNotFoundException(f"The conn_id `{conn_id}` isn't defined")
airflow.exceptions.AirflowNotFoundException: The conn_id `opentax_postgres_conn` isn't defined

During handling of the above exception, another exception occurred:

Traceback (most recent call last):
  File "/home/airflow/.local/lib/python3.12/site-packages/airflow/models/taskinstance.py", line 465, in _execute_task
    result = _execute_callable(context=context, **execute_callable_kwargs)
             ^^^^^^^^^^^^^^^^^^^^^^^^^^^^^^^^^^^^^^^^^^^^^^^^^^^^^^^^^^^^^
  File "/home/airflow/.local/lib/python3.12/site-packages/airflow/models/taskinstance.py", line 432, in _execute_callable
    return execute_callable(context=context, **execute_callable_kwargs)
           ^^^^^^^^^^^^^^^^^^^^^^^^^^^^^^^^^^^^^^^^^^^^^^^^^^^^^^^^^^^^
  File "/home/airflow/.local/lib/python3.12/site-packages/airflow/models/baseoperator.py", line 401, in wrapper
    return func(self, *args, **kwargs)
           ^^^^^^^^^^^^^^^^^^^^^^^^^^^
  File "/home/airflow/.local/lib/python3.12/site-packages/airflow/operators/python.py", line 235, in execute
    return_value = self.execute_callable()
                   ^^^^^^^^^^^^^^^^^^^^^^^
  File "/home/airflow/.local/lib/python3.12/site-packages/airflow/operators/python.py", line 252, in execute_callable
    return self.python_callable(*self.op_args, **self.op_kwargs)
           ^^^^^^^^^^^^^^^^^^^^^^^^^^^^^^^^^^^^^^^^^^^^^^^^^^^^^
  File "/opt/airflow/dags/opentaxetl.py", line 53, in extract_transactional_data
    audit_logs(dag_id,task_id,'ERROR',str(e))
  File "/opt/airflow/dags/pipeline_logs.py", line 14, in audit_logs
    postgres_hook_engine = PostgresHook(postgres_conn_id='opentax_postgres_conn').get_sqlalchemy_engine()
                           ^^^^^^^^^^^^^^^^^^^^^^^^^^^^^^^^^^^^^^^^^^^^^^^^^^^^^^^^^^^^^^^^^^^^^^^^^^^^^^
  File "/home/airflow/.local/lib/python3.12/site-packages/airflow/providers/common/sql/hooks/sql.py", line 245, in get_sqlalchemy_engine
    return create_engine(self.get_uri(), **engine_kwargs)
                         ^^^^^^^^^^^^^^
  File "/home/airflow/.local/lib/python3.12/site-packages/airflow/providers/postgres/hooks/postgres.py", line 204, in get_uri
    return self.sqlalchemy_url.render_as_string(hide_password=False)
           ^^^^^^^^^^^^^^^^^^^
  File "/home/airflow/.local/lib/python3.12/site-packages/airflow/providers/postgres/hooks/postgres.py", line 119, in sqlalchemy_url
    conn = self.get_connection(getattr(self, self.conn_name_attr))
           ^^^^^^^^^^^^^^^^^^^^^^^^^^^^^^^^^^^^^^^^^^^^^^^^^^^^^^^
  File "/home/airflow/.local/lib/python3.12/site-packages/airflow/hooks/base.py", line 83, in get_connection
    conn = Connection.get_connection_from_secrets(conn_id)
           ^^^^^^^^^^^^^^^^^^^^^^^^^^^^^^^^^^^^^^^^^^^^^^^
  File "/home/airflow/.local/lib/python3.12/site-packages/airflow/models/connection.py", line 519, in get_connection_from_secrets
    raise AirflowNotFoundException(f"The conn_id `{conn_id}` isn't defined")
airflow.exceptions.AirflowNotFoundException: The conn_id `opentax_postgres_conn` isn't defined
[2025-02-24T07:28:49.415+0000] {taskinstance.py:1206} INFO - Marking task as FAILED. dag_id=open_tax_etl, task_id=extract_task, run_id=scheduled__2023-01-01T00:00:00+00:00, execution_date=20230101T000000, start_date=20250224T072842, end_date=20250224T072849
[2025-02-24T07:28:49.583+0000] {standard_task_runner.py:110} ERROR - Failed to execute job 3 for task extract_task (The conn_id `opentax_postgres_conn` isn't defined; 288)
[2025-02-24T07:28:49.618+0000] {local_task_job_runner.py:243} INFO - Task exited with return code 1
[2025-02-24T07:28:49.802+0000] {taskinstance.py:3503} INFO - 0 downstream tasks scheduled from follow-on schedule check
[2025-02-24T07:28:49.818+0000] {local_task_job_runner.py:222} INFO - ::endgroup::
[2025-02-24T13:08:22.250+0000] {local_task_job_runner.py:120} INFO - ::group::Pre task execution logs
[2025-02-24T13:08:22.281+0000] {taskinstance.py:2076} INFO - Dependencies all met for dep_context=non-requeueable deps ti=<TaskInstance: open_tax_etl.extract_task scheduled__2023-01-01T00:00:00+00:00 [queued]>
[2025-02-24T13:08:22.289+0000] {taskinstance.py:2076} INFO - Dependencies all met for dep_context=requeueable deps ti=<TaskInstance: open_tax_etl.extract_task scheduled__2023-01-01T00:00:00+00:00 [queued]>
[2025-02-24T13:08:22.290+0000] {taskinstance.py:2306} INFO - Starting attempt 1 of 1
[2025-02-24T13:08:22.301+0000] {taskinstance.py:2330} INFO - Executing <Task(PythonOperator): extract_task> on 2023-01-01 00:00:00+00:00
[2025-02-24T13:08:22.316+0000] {logging_mixin.py:188} WARNING - /home/airflow/.local/lib/python3.12/site-packages/airflow/task/task_runner/standard_task_runner.py:62 DeprecationWarning: This process (pid=265) is multi-threaded, use of fork() may lead to deadlocks in the child.
[2025-02-24T13:08:22.311+0000] {standard_task_runner.py:90} INFO - Running: ['airflow', 'tasks', 'run', 'open_tax_etl', 'extract_task', 'scheduled__2023-01-01T00:00:00+00:00', '--job-id', '7', '--raw', '--subdir', 'DAGS_FOLDER/opentaxetl.py', '--cfg-path', '/tmp/tmpiuqwqcef']
[2025-02-24T13:08:22.318+0000] {standard_task_runner.py:64} INFO - Started process 268 to run task
[2025-02-24T13:08:22.318+0000] {standard_task_runner.py:91} INFO - Job 7: Subtask extract_task
[2025-02-24T13:08:22.371+0000] {task_command.py:426} INFO - Running <TaskInstance: open_tax_etl.extract_task scheduled__2023-01-01T00:00:00+00:00 [running]> on host 267c2ff1bd58
[2025-02-24T13:08:22.459+0000] {taskinstance.py:2648} INFO - Exporting env vars: AIRFLOW_CTX_DAG_OWNER='airflow' AIRFLOW_CTX_DAG_ID='open_tax_etl' AIRFLOW_CTX_TASK_ID='extract_task' AIRFLOW_CTX_EXECUTION_DATE='2023-01-01T00:00:00+00:00' AIRFLOW_CTX_TRY_NUMBER='1' AIRFLOW_CTX_DAG_RUN_ID='scheduled__2023-01-01T00:00:00+00:00'
[2025-02-24T13:08:22.461+0000] {taskinstance.py:430} INFO - ::endgroup::
[2025-02-24T13:08:22.791+0000] {opentaxetl.py:35} INFO - Beginning to extract data from source
[2025-02-24T13:08:22.871+0000] {taskinstance.py:441} INFO - ::group::Post task execution logs
[2025-02-24T13:08:22.872+0000] {taskinstance.py:2905} ERROR - Task failed with exception
Traceback (most recent call last):
  File "/opt/airflow/dags/pipeline_logs.py", line 30, in audit_logs
    postgres_hook_engine = PostgresHook(postgres_conn_id='opentax_postgres_conn').get_sqlalchemy_engine()
                           ^^^^^^^^^^^^^^^^^^^^^^^^^^^^^^^^^^^^^^^^^^^^^^^^^^^^^^^^^^^^^^^^^^^^^^^^^^^^^^
  File "/home/airflow/.local/lib/python3.12/site-packages/airflow/providers/common/sql/hooks/sql.py", line 245, in get_sqlalchemy_engine
    return create_engine(self.get_uri(), **engine_kwargs)
                         ^^^^^^^^^^^^^^
  File "/home/airflow/.local/lib/python3.12/site-packages/airflow/providers/postgres/hooks/postgres.py", line 204, in get_uri
    return self.sqlalchemy_url.render_as_string(hide_password=False)
           ^^^^^^^^^^^^^^^^^^^
  File "/home/airflow/.local/lib/python3.12/site-packages/airflow/providers/postgres/hooks/postgres.py", line 119, in sqlalchemy_url
    conn = self.get_connection(getattr(self, self.conn_name_attr))
           ^^^^^^^^^^^^^^^^^^^^^^^^^^^^^^^^^^^^^^^^^^^^^^^^^^^^^^^
  File "/home/airflow/.local/lib/python3.12/site-packages/airflow/hooks/base.py", line 83, in get_connection
    conn = Connection.get_connection_from_secrets(conn_id)
           ^^^^^^^^^^^^^^^^^^^^^^^^^^^^^^^^^^^^^^^^^^^^^^^
  File "/home/airflow/.local/lib/python3.12/site-packages/airflow/models/connection.py", line 519, in get_connection_from_secrets
    raise AirflowNotFoundException(f"The conn_id `{conn_id}` isn't defined")
airflow.exceptions.AirflowNotFoundException: The conn_id `opentax_postgres_conn` isn't defined

During handling of the above exception, another exception occurred:

Traceback (most recent call last):
  File "/opt/airflow/dags/opentaxetl.py", line 47, in extract_transactional_data
    audit_logs(dag_id,task_id,'INFO','Succesfully Extracted Data from CSV')
  File "/opt/airflow/dags/pipeline_logs.py", line 35, in audit_logs
    except SQLAlchemyError as e:
           ^^^^^^^^^^^^^^^
NameError: name 'SQLAlchemyError' is not defined

During handling of the above exception, another exception occurred:

Traceback (most recent call last):
  File "/opt/airflow/dags/pipeline_logs.py", line 30, in audit_logs
    postgres_hook_engine = PostgresHook(postgres_conn_id='opentax_postgres_conn').get_sqlalchemy_engine()
                           ^^^^^^^^^^^^^^^^^^^^^^^^^^^^^^^^^^^^^^^^^^^^^^^^^^^^^^^^^^^^^^^^^^^^^^^^^^^^^^
  File "/home/airflow/.local/lib/python3.12/site-packages/airflow/providers/common/sql/hooks/sql.py", line 245, in get_sqlalchemy_engine
    return create_engine(self.get_uri(), **engine_kwargs)
                         ^^^^^^^^^^^^^^
  File "/home/airflow/.local/lib/python3.12/site-packages/airflow/providers/postgres/hooks/postgres.py", line 204, in get_uri
    return self.sqlalchemy_url.render_as_string(hide_password=False)
           ^^^^^^^^^^^^^^^^^^^
  File "/home/airflow/.local/lib/python3.12/site-packages/airflow/providers/postgres/hooks/postgres.py", line 119, in sqlalchemy_url
    conn = self.get_connection(getattr(self, self.conn_name_attr))
           ^^^^^^^^^^^^^^^^^^^^^^^^^^^^^^^^^^^^^^^^^^^^^^^^^^^^^^^
  File "/home/airflow/.local/lib/python3.12/site-packages/airflow/hooks/base.py", line 83, in get_connection
    conn = Connection.get_connection_from_secrets(conn_id)
           ^^^^^^^^^^^^^^^^^^^^^^^^^^^^^^^^^^^^^^^^^^^^^^^
  File "/home/airflow/.local/lib/python3.12/site-packages/airflow/models/connection.py", line 519, in get_connection_from_secrets
    raise AirflowNotFoundException(f"The conn_id `{conn_id}` isn't defined")
airflow.exceptions.AirflowNotFoundException: The conn_id `opentax_postgres_conn` isn't defined

During handling of the above exception, another exception occurred:

Traceback (most recent call last):
  File "/home/airflow/.local/lib/python3.12/site-packages/airflow/models/taskinstance.py", line 465, in _execute_task
    result = _execute_callable(context=context, **execute_callable_kwargs)
             ^^^^^^^^^^^^^^^^^^^^^^^^^^^^^^^^^^^^^^^^^^^^^^^^^^^^^^^^^^^^^
  File "/home/airflow/.local/lib/python3.12/site-packages/airflow/models/taskinstance.py", line 432, in _execute_callable
    return execute_callable(context=context, **execute_callable_kwargs)
           ^^^^^^^^^^^^^^^^^^^^^^^^^^^^^^^^^^^^^^^^^^^^^^^^^^^^^^^^^^^^
  File "/home/airflow/.local/lib/python3.12/site-packages/airflow/models/baseoperator.py", line 401, in wrapper
    return func(self, *args, **kwargs)
           ^^^^^^^^^^^^^^^^^^^^^^^^^^^
  File "/home/airflow/.local/lib/python3.12/site-packages/airflow/operators/python.py", line 235, in execute
    return_value = self.execute_callable()
                   ^^^^^^^^^^^^^^^^^^^^^^^
  File "/home/airflow/.local/lib/python3.12/site-packages/airflow/operators/python.py", line 252, in execute_callable
    return self.python_callable(*self.op_args, **self.op_kwargs)
           ^^^^^^^^^^^^^^^^^^^^^^^^^^^^^^^^^^^^^^^^^^^^^^^^^^^^^
  File "/opt/airflow/dags/opentaxetl.py", line 53, in extract_transactional_data
    audit_logs(dag_id,task_id,'ERROR',str(e))
  File "/opt/airflow/dags/pipeline_logs.py", line 35, in audit_logs
    except SQLAlchemyError as e:
           ^^^^^^^^^^^^^^^
NameError: name 'SQLAlchemyError' is not defined
[2025-02-24T13:08:22.887+0000] {taskinstance.py:1206} INFO - Marking task as FAILED. dag_id=open_tax_etl, task_id=extract_task, run_id=scheduled__2023-01-01T00:00:00+00:00, execution_date=20230101T000000, start_date=20250224T130822, end_date=20250224T130822
[2025-02-24T13:08:22.900+0000] {standard_task_runner.py:110} ERROR - Failed to execute job 7 for task extract_task (name 'SQLAlchemyError' is not defined; 268)
[2025-02-24T13:08:22.954+0000] {local_task_job_runner.py:243} INFO - Task exited with return code 1
[2025-02-24T13:08:22.979+0000] {taskinstance.py:3503} INFO - 0 downstream tasks scheduled from follow-on schedule check
[2025-02-24T13:08:22.984+0000] {local_task_job_runner.py:222} INFO - ::endgroup::
[2025-02-24T14:16:15.798+0000] {local_task_job_runner.py:120} INFO - ::group::Pre task execution logs
[2025-02-24T14:16:15.871+0000] {taskinstance.py:2076} INFO - Dependencies all met for dep_context=non-requeueable deps ti=<TaskInstance: open_tax_etl.extract_task scheduled__2023-01-01T00:00:00+00:00 [queued]>
[2025-02-24T14:16:15.883+0000] {taskinstance.py:2076} INFO - Dependencies all met for dep_context=requeueable deps ti=<TaskInstance: open_tax_etl.extract_task scheduled__2023-01-01T00:00:00+00:00 [queued]>
[2025-02-24T14:16:15.884+0000] {taskinstance.py:2306} INFO - Starting attempt 1 of 1
[2025-02-24T14:16:15.908+0000] {taskinstance.py:2330} INFO - Executing <Task(PythonOperator): extract_task> on 2023-01-01 00:00:00+00:00
[2025-02-24T14:16:15.926+0000] {standard_task_runner.py:90} INFO - Running: ['airflow', 'tasks', 'run', 'open_tax_etl', 'extract_task', 'scheduled__2023-01-01T00:00:00+00:00', '--job-id', '3', '--raw', '--subdir', 'DAGS_FOLDER/opentaxetl.py', '--cfg-path', '/tmp/tmphnfz_pcm']
[2025-02-24T14:16:15.929+0000] {standard_task_runner.py:91} INFO - Job 3: Subtask extract_task
[2025-02-24T14:16:15.939+0000] {logging_mixin.py:188} WARNING - /home/airflow/.local/lib/python3.12/site-packages/airflow/task/task_runner/standard_task_runner.py:62 DeprecationWarning: This process (pid=256) is multi-threaded, use of fork() may lead to deadlocks in the child.
[2025-02-24T14:16:15.940+0000] {standard_task_runner.py:64} INFO - Started process 261 to run task
[2025-02-24T14:16:16.062+0000] {task_command.py:426} INFO - Running <TaskInstance: open_tax_etl.extract_task scheduled__2023-01-01T00:00:00+00:00 [running]> on host d4ea9a98a6d8
[2025-02-24T14:16:16.245+0000] {taskinstance.py:2648} INFO - Exporting env vars: AIRFLOW_CTX_DAG_OWNER='airflow' AIRFLOW_CTX_DAG_ID='open_tax_etl' AIRFLOW_CTX_TASK_ID='extract_task' AIRFLOW_CTX_EXECUTION_DATE='2023-01-01T00:00:00+00:00' AIRFLOW_CTX_TRY_NUMBER='1' AIRFLOW_CTX_DAG_RUN_ID='scheduled__2023-01-01T00:00:00+00:00'
[2025-02-24T14:16:16.248+0000] {taskinstance.py:430} INFO - ::endgroup::
[2025-02-24T14:16:17.922+0000] {opentaxetl.py:35} INFO - Beginning to extract data from source
[2025-02-24T14:16:18.064+0000] {taskinstance.py:441} INFO - ::group::Post task execution logs
[2025-02-24T14:16:18.065+0000] {taskinstance.py:2905} ERROR - Task failed with exception
Traceback (most recent call last):
  File "/opt/airflow/dags/pipeline_logs.py", line 30, in audit_logs
    postgres_hook_engine = PostgresHook(postgres_conn_id='opentax_postgres_conn').get_sqlalchemy_engine()
                           ^^^^^^^^^^^^^^^^^^^^^^^^^^^^^^^^^^^^^^^^^^^^^^^^^^^^^^^^^^^^^^^^^^^^^^^^^^^^^^
  File "/home/airflow/.local/lib/python3.12/site-packages/airflow/providers/common/sql/hooks/sql.py", line 245, in get_sqlalchemy_engine
    return create_engine(self.get_uri(), **engine_kwargs)
                         ^^^^^^^^^^^^^^
  File "/home/airflow/.local/lib/python3.12/site-packages/airflow/providers/postgres/hooks/postgres.py", line 204, in get_uri
    return self.sqlalchemy_url.render_as_string(hide_password=False)
           ^^^^^^^^^^^^^^^^^^^
  File "/home/airflow/.local/lib/python3.12/site-packages/airflow/providers/postgres/hooks/postgres.py", line 119, in sqlalchemy_url
    conn = self.get_connection(getattr(self, self.conn_name_attr))
           ^^^^^^^^^^^^^^^^^^^^^^^^^^^^^^^^^^^^^^^^^^^^^^^^^^^^^^^
  File "/home/airflow/.local/lib/python3.12/site-packages/airflow/hooks/base.py", line 83, in get_connection
    conn = Connection.get_connection_from_secrets(conn_id)
           ^^^^^^^^^^^^^^^^^^^^^^^^^^^^^^^^^^^^^^^^^^^^^^^
  File "/home/airflow/.local/lib/python3.12/site-packages/airflow/models/connection.py", line 519, in get_connection_from_secrets
    raise AirflowNotFoundException(f"The conn_id `{conn_id}` isn't defined")
airflow.exceptions.AirflowNotFoundException: The conn_id `opentax_postgres_conn` isn't defined

During handling of the above exception, another exception occurred:

Traceback (most recent call last):
  File "/opt/airflow/dags/opentaxetl.py", line 47, in extract_transactional_data
    audit_logs(dag_id,task_id,'INFO','Succesfully Extracted Data from CSV')
  File "/opt/airflow/dags/pipeline_logs.py", line 35, in audit_logs
    except SQLAlchemyError as e:
           ^^^^^^^^^^^^^^^
NameError: name 'SQLAlchemyError' is not defined

During handling of the above exception, another exception occurred:

Traceback (most recent call last):
  File "/opt/airflow/dags/pipeline_logs.py", line 30, in audit_logs
    postgres_hook_engine = PostgresHook(postgres_conn_id='opentax_postgres_conn').get_sqlalchemy_engine()
                           ^^^^^^^^^^^^^^^^^^^^^^^^^^^^^^^^^^^^^^^^^^^^^^^^^^^^^^^^^^^^^^^^^^^^^^^^^^^^^^
  File "/home/airflow/.local/lib/python3.12/site-packages/airflow/providers/common/sql/hooks/sql.py", line 245, in get_sqlalchemy_engine
    return create_engine(self.get_uri(), **engine_kwargs)
                         ^^^^^^^^^^^^^^
  File "/home/airflow/.local/lib/python3.12/site-packages/airflow/providers/postgres/hooks/postgres.py", line 204, in get_uri
    return self.sqlalchemy_url.render_as_string(hide_password=False)
           ^^^^^^^^^^^^^^^^^^^
  File "/home/airflow/.local/lib/python3.12/site-packages/airflow/providers/postgres/hooks/postgres.py", line 119, in sqlalchemy_url
    conn = self.get_connection(getattr(self, self.conn_name_attr))
           ^^^^^^^^^^^^^^^^^^^^^^^^^^^^^^^^^^^^^^^^^^^^^^^^^^^^^^^
  File "/home/airflow/.local/lib/python3.12/site-packages/airflow/hooks/base.py", line 83, in get_connection
    conn = Connection.get_connection_from_secrets(conn_id)
           ^^^^^^^^^^^^^^^^^^^^^^^^^^^^^^^^^^^^^^^^^^^^^^^
  File "/home/airflow/.local/lib/python3.12/site-packages/airflow/models/connection.py", line 519, in get_connection_from_secrets
    raise AirflowNotFoundException(f"The conn_id `{conn_id}` isn't defined")
airflow.exceptions.AirflowNotFoundException: The conn_id `opentax_postgres_conn` isn't defined

During handling of the above exception, another exception occurred:

Traceback (most recent call last):
  File "/home/airflow/.local/lib/python3.12/site-packages/airflow/models/taskinstance.py", line 465, in _execute_task
    result = _execute_callable(context=context, **execute_callable_kwargs)
             ^^^^^^^^^^^^^^^^^^^^^^^^^^^^^^^^^^^^^^^^^^^^^^^^^^^^^^^^^^^^^
  File "/home/airflow/.local/lib/python3.12/site-packages/airflow/models/taskinstance.py", line 432, in _execute_callable
    return execute_callable(context=context, **execute_callable_kwargs)
           ^^^^^^^^^^^^^^^^^^^^^^^^^^^^^^^^^^^^^^^^^^^^^^^^^^^^^^^^^^^^
  File "/home/airflow/.local/lib/python3.12/site-packages/airflow/models/baseoperator.py", line 401, in wrapper
    return func(self, *args, **kwargs)
           ^^^^^^^^^^^^^^^^^^^^^^^^^^^
  File "/home/airflow/.local/lib/python3.12/site-packages/airflow/operators/python.py", line 235, in execute
    return_value = self.execute_callable()
                   ^^^^^^^^^^^^^^^^^^^^^^^
  File "/home/airflow/.local/lib/python3.12/site-packages/airflow/operators/python.py", line 252, in execute_callable
    return self.python_callable(*self.op_args, **self.op_kwargs)
           ^^^^^^^^^^^^^^^^^^^^^^^^^^^^^^^^^^^^^^^^^^^^^^^^^^^^^
  File "/opt/airflow/dags/opentaxetl.py", line 53, in extract_transactional_data
    audit_logs(dag_id,task_id,'ERROR',str(e))
  File "/opt/airflow/dags/pipeline_logs.py", line 35, in audit_logs
    except SQLAlchemyError as e:
           ^^^^^^^^^^^^^^^
NameError: name 'SQLAlchemyError' is not defined
[2025-02-24T14:16:18.092+0000] {taskinstance.py:1206} INFO - Marking task as FAILED. dag_id=open_tax_etl, task_id=extract_task, run_id=scheduled__2023-01-01T00:00:00+00:00, execution_date=20230101T000000, start_date=20250224T141615, end_date=20250224T141618
[2025-02-24T14:16:18.118+0000] {standard_task_runner.py:110} ERROR - Failed to execute job 3 for task extract_task (name 'SQLAlchemyError' is not defined; 261)
[2025-02-24T14:16:18.152+0000] {local_task_job_runner.py:243} INFO - Task exited with return code 1
[2025-02-24T14:16:18.206+0000] {taskinstance.py:3503} INFO - 0 downstream tasks scheduled from follow-on schedule check
[2025-02-24T14:16:18.211+0000] {local_task_job_runner.py:222} INFO - ::endgroup::
[2025-02-24T15:07:40.965+0000] {local_task_job_runner.py:120} INFO - ::group::Pre task execution logs
[2025-02-24T15:07:41.034+0000] {taskinstance.py:2076} INFO - Dependencies all met for dep_context=non-requeueable deps ti=<TaskInstance: open_tax_etl.extract_task scheduled__2023-01-01T00:00:00+00:00 [queued]>
[2025-02-24T15:07:41.053+0000] {taskinstance.py:2076} INFO - Dependencies all met for dep_context=requeueable deps ti=<TaskInstance: open_tax_etl.extract_task scheduled__2023-01-01T00:00:00+00:00 [queued]>
[2025-02-24T15:07:41.055+0000] {taskinstance.py:2306} INFO - Starting attempt 1 of 1
[2025-02-24T15:07:41.076+0000] {taskinstance.py:2330} INFO - Executing <Task(PythonOperator): extract_task> on 2023-01-01 00:00:00+00:00
[2025-02-24T15:07:41.107+0000] {logging_mixin.py:188} WARNING - /home/airflow/.local/lib/python3.12/site-packages/airflow/task/task_runner/standard_task_runner.py:62 DeprecationWarning: This process (pid=284) is multi-threaded, use of fork() may lead to deadlocks in the child.
[2025-02-24T15:07:41.111+0000] {standard_task_runner.py:64} INFO - Started process 293 to run task
[2025-02-24T15:07:41.107+0000] {standard_task_runner.py:90} INFO - Running: ['airflow', 'tasks', 'run', 'open_tax_etl', 'extract_task', 'scheduled__2023-01-01T00:00:00+00:00', '--job-id', '3', '--raw', '--subdir', 'DAGS_FOLDER/opentaxetl.py', '--cfg-path', '/tmp/tmp5fc6x6jt']
[2025-02-24T15:07:41.118+0000] {standard_task_runner.py:91} INFO - Job 3: Subtask extract_task
[2025-02-24T15:07:41.285+0000] {task_command.py:426} INFO - Running <TaskInstance: open_tax_etl.extract_task scheduled__2023-01-01T00:00:00+00:00 [running]> on host 4b9ec98fde54
[2025-02-24T15:07:41.396+0000] {taskinstance.py:2648} INFO - Exporting env vars: AIRFLOW_CTX_DAG_OWNER='airflow' AIRFLOW_CTX_DAG_ID='open_tax_etl' AIRFLOW_CTX_TASK_ID='extract_task' AIRFLOW_CTX_EXECUTION_DATE='2023-01-01T00:00:00+00:00' AIRFLOW_CTX_TRY_NUMBER='1' AIRFLOW_CTX_DAG_RUN_ID='scheduled__2023-01-01T00:00:00+00:00'
[2025-02-24T15:07:41.399+0000] {taskinstance.py:430} INFO - ::endgroup::
[2025-02-24T15:07:42.593+0000] {opentaxetl.py:35} INFO - Beginning to extract data from source
[2025-02-24T15:07:42.704+0000] {base.py:84} INFO - Using connection ID 'opentax_postgres_conn' for task execution.
[2025-02-24T15:07:42.746+0000] {opentaxetl.py:48} INFO - Data Extraction Completed
[2025-02-24T15:07:42.748+0000] {python.py:237} INFO - Done. Returned value was: None
[2025-02-24T15:07:42.750+0000] {taskinstance.py:441} INFO - ::group::Post task execution logs
[2025-02-24T15:07:42.786+0000] {taskinstance.py:1206} INFO - Marking task as SUCCESS. dag_id=open_tax_etl, task_id=extract_task, run_id=scheduled__2023-01-01T00:00:00+00:00, execution_date=20230101T000000, start_date=20250224T150741, end_date=20250224T150742
[2025-02-24T15:07:42.871+0000] {local_task_job_runner.py:243} INFO - Task exited with return code 0
[2025-02-24T15:07:42.907+0000] {taskinstance.py:3503} INFO - 1 downstream tasks scheduled from follow-on schedule check
[2025-02-24T15:07:42.912+0000] {local_task_job_runner.py:222} INFO - ::endgroup::
