[2025-02-23T11:34:56.861+0000] {local_task_job_runner.py:120} INFO - ::group::Pre task execution logs
[2025-02-23T11:34:56.885+0000] {taskinstance.py:2076} INFO - Dependencies all met for dep_context=non-requeueable deps ti=<TaskInstance: open_tax_etl.load_task manual__2025-02-23T11:34:51.304291+00:00 [queued]>
[2025-02-23T11:34:56.891+0000] {taskinstance.py:2076} INFO - Dependencies all met for dep_context=requeueable deps ti=<TaskInstance: open_tax_etl.load_task manual__2025-02-23T11:34:51.304291+00:00 [queued]>
[2025-02-23T11:34:56.892+0000] {taskinstance.py:2306} INFO - Starting attempt 1 of 1
[2025-02-23T11:34:56.899+0000] {taskinstance.py:2330} INFO - Executing <Task(PythonOperator): load_task> on 2025-02-23 11:34:51.304291+00:00
[2025-02-23T11:34:56.905+0000] {standard_task_runner.py:90} INFO - Running: ['airflow', 'tasks', 'run', 'open_tax_etl', 'load_task', 'manual__2025-02-23T11:34:51.304291+00:00', '--job-id', '56', '--raw', '--subdir', 'DAGS_FOLDER/opentaxetl.py', '--cfg-path', '/tmp/tmpa5w742p7']
[2025-02-23T11:34:56.908+0000] {standard_task_runner.py:91} INFO - Job 56: Subtask load_task
[2025-02-23T11:34:56.908+0000] {logging_mixin.py:188} WARNING - /home/airflow/.local/lib/python3.12/site-packages/airflow/task/task_runner/standard_task_runner.py:62 DeprecationWarning: This process (pid=2115) is multi-threaded, use of fork() may lead to deadlocks in the child.
[2025-02-23T11:34:56.910+0000] {standard_task_runner.py:64} INFO - Started process 2117 to run task
[2025-02-23T11:34:56.957+0000] {task_command.py:426} INFO - Running <TaskInstance: open_tax_etl.load_task manual__2025-02-23T11:34:51.304291+00:00 [running]> on host 2cf524a0af0b
[2025-02-23T11:34:57.173+0000] {taskinstance.py:2648} INFO - Exporting env vars: AIRFLOW_CTX_DAG_OWNER='airflow' AIRFLOW_CTX_DAG_ID='open_tax_etl' AIRFLOW_CTX_TASK_ID='load_task' AIRFLOW_CTX_EXECUTION_DATE='2025-02-23T11:34:51.304291+00:00' AIRFLOW_CTX_TRY_NUMBER='1' AIRFLOW_CTX_DAG_RUN_ID='manual__2025-02-23T11:34:51.304291+00:00'
[2025-02-23T11:34:57.174+0000] {taskinstance.py:430} INFO - ::endgroup::
[2025-02-23T11:34:57.201+0000] {base.py:84} INFO - Using connection ID 'opentax_postgres_conn' for task execution.
[2025-02-23T11:34:57.231+0000] {taskinstance.py:441} INFO - ::group::Post task execution logs
[2025-02-23T11:34:57.232+0000] {taskinstance.py:2905} ERROR - Task failed with exception
Traceback (most recent call last):
  File "/home/airflow/.local/lib/python3.12/site-packages/sqlalchemy/engine/base.py", line 1890, in _execute_context
    self.dialect.do_executemany(
  File "/home/airflow/.local/lib/python3.12/site-packages/sqlalchemy/dialects/postgresql/psycopg2.py", line 982, in do_executemany
    context._psycopg2_fetched_rows = xtras.execute_values(
                                     ^^^^^^^^^^^^^^^^^^^^^
  File "/home/airflow/.local/lib/python3.12/site-packages/psycopg2/extras.py", line 1299, in execute_values
    cur.execute(b''.join(parts))
psycopg2.errors.NotNullViolation: null value in column "transaction_date" of relation "transactions" violates not-null constraint
DETAIL:  Failing row contains (TXN749110, 1716, null, null).


The above exception was the direct cause of the following exception:

Traceback (most recent call last):
  File "/home/airflow/.local/lib/python3.12/site-packages/airflow/models/taskinstance.py", line 465, in _execute_task
    result = _execute_callable(context=context, **execute_callable_kwargs)
             ^^^^^^^^^^^^^^^^^^^^^^^^^^^^^^^^^^^^^^^^^^^^^^^^^^^^^^^^^^^^^
  File "/home/airflow/.local/lib/python3.12/site-packages/airflow/models/taskinstance.py", line 432, in _execute_callable
    return execute_callable(context=context, **execute_callable_kwargs)
           ^^^^^^^^^^^^^^^^^^^^^^^^^^^^^^^^^^^^^^^^^^^^^^^^^^^^^^^^^^^^
  File "/home/airflow/.local/lib/python3.12/site-packages/airflow/models/baseoperator.py", line 401, in wrapper
    return func(self, *args, **kwargs)
           ^^^^^^^^^^^^^^^^^^^^^^^^^^^
  File "/home/airflow/.local/lib/python3.12/site-packages/airflow/operators/python.py", line 235, in execute
    return_value = self.execute_callable()
                   ^^^^^^^^^^^^^^^^^^^^^^^
  File "/home/airflow/.local/lib/python3.12/site-packages/airflow/operators/python.py", line 252, in execute_callable
    return self.python_callable(*self.op_args, **self.op_kwargs)
           ^^^^^^^^^^^^^^^^^^^^^^^^^^^^^^^^^^^^^^^^^^^^^^^^^^^^^
  File "/opt/airflow/dags/opentaxetl.py", line 67, in load_transactional_data
    df.to_sql('transactions', con=engine, if_exists='append', index=False)
  File "/home/airflow/.local/lib/python3.12/site-packages/pandas/util/_decorators.py", line 333, in wrapper
    return func(*args, **kwargs)
           ^^^^^^^^^^^^^^^^^^^^^
  File "/home/airflow/.local/lib/python3.12/site-packages/pandas/core/generic.py", line 3008, in to_sql
    return sql.to_sql(
           ^^^^^^^^^^^
  File "/home/airflow/.local/lib/python3.12/site-packages/pandas/io/sql.py", line 788, in to_sql
    return pandas_sql.to_sql(
           ^^^^^^^^^^^^^^^^^^
  File "/home/airflow/.local/lib/python3.12/site-packages/pandas/io/sql.py", line 1958, in to_sql
    total_inserted = sql_engine.insert_records(
                     ^^^^^^^^^^^^^^^^^^^^^^^^^^
  File "/home/airflow/.local/lib/python3.12/site-packages/pandas/io/sql.py", line 1507, in insert_records
    raise err
  File "/home/airflow/.local/lib/python3.12/site-packages/pandas/io/sql.py", line 1498, in insert_records
    return table.insert(chunksize=chunksize, method=method)
           ^^^^^^^^^^^^^^^^^^^^^^^^^^^^^^^^^^^^^^^^^^^^^^^^
  File "/home/airflow/.local/lib/python3.12/site-packages/pandas/io/sql.py", line 1059, in insert
    num_inserted = exec_insert(conn, keys, chunk_iter)
                   ^^^^^^^^^^^^^^^^^^^^^^^^^^^^^^^^^^^
  File "/home/airflow/.local/lib/python3.12/site-packages/pandas/io/sql.py", line 951, in _execute_insert
    result = conn.execute(self.table.insert(), data)
             ^^^^^^^^^^^^^^^^^^^^^^^^^^^^^^^^^^^^^^^
  File "/home/airflow/.local/lib/python3.12/site-packages/sqlalchemy/engine/base.py", line 1385, in execute
    return meth(self, multiparams, params, _EMPTY_EXECUTION_OPTS)
           ^^^^^^^^^^^^^^^^^^^^^^^^^^^^^^^^^^^^^^^^^^^^^^^^^^^^^^
  File "/home/airflow/.local/lib/python3.12/site-packages/sqlalchemy/sql/elements.py", line 334, in _execute_on_connection
    return connection._execute_clauseelement(
           ^^^^^^^^^^^^^^^^^^^^^^^^^^^^^^^^^^
  File "/home/airflow/.local/lib/python3.12/site-packages/sqlalchemy/engine/base.py", line 1577, in _execute_clauseelement
    ret = self._execute_context(
          ^^^^^^^^^^^^^^^^^^^^^^
  File "/home/airflow/.local/lib/python3.12/site-packages/sqlalchemy/engine/base.py", line 1953, in _execute_context
    self._handle_dbapi_exception(
  File "/home/airflow/.local/lib/python3.12/site-packages/sqlalchemy/engine/base.py", line 2134, in _handle_dbapi_exception
    util.raise_(
  File "/home/airflow/.local/lib/python3.12/site-packages/sqlalchemy/util/compat.py", line 211, in raise_
    raise exception
  File "/home/airflow/.local/lib/python3.12/site-packages/sqlalchemy/engine/base.py", line 1890, in _execute_context
    self.dialect.do_executemany(
  File "/home/airflow/.local/lib/python3.12/site-packages/sqlalchemy/dialects/postgresql/psycopg2.py", line 982, in do_executemany
    context._psycopg2_fetched_rows = xtras.execute_values(
                                     ^^^^^^^^^^^^^^^^^^^^^
  File "/home/airflow/.local/lib/python3.12/site-packages/psycopg2/extras.py", line 1299, in execute_values
    cur.execute(b''.join(parts))
sqlalchemy.exc.IntegrityError: (psycopg2.errors.NotNullViolation) null value in column "transaction_date" of relation "transactions" violates not-null constraint
DETAIL:  Failing row contains (TXN749110, 1716, null, null).

[SQL: INSERT INTO transactions (transaction_id, user_id, amount, transaction_date) VALUES (%(transaction_id)s, %(user_id)s, %(amount)s, %(transaction_date)s)]
[parameters: ({'transaction_id': 'TXN204793', 'user_id': 1408, 'amount': 0.0, 'transaction_date': '2024-07-11'}, {'transaction_id': 'TXN749110', 'user_id': 1716, 'amount': None, 'transaction_date': None}, {'transaction_id': 'TXN984574', 'user_id': 1934, 'amount': None, 'transaction_date': None}, {'transaction_id': 'TXN180036', 'user_id': 1034, 'amount': -3437.55, 'transaction_date': None}, {'transaction_id': 'TXN147245', 'user_id': 1497, 'amount': 0.0, 'transaction_date': None}, {'transaction_id': 'TXN258146', 'user_id': 1616, 'amount': -1127.9, 'transaction_date': '2024-04-09'}, {'transaction_id': 'TXN372021', 'user_id': 1269, 'amount': 4990.0, 'transaction_date': None}, {'transaction_id': 'TXN205034', 'user_id': 1445, 'amount': 906.17, 'transaction_date': None}  ... displaying 10 of 1000 total bound parameter sets ...  {'transaction_id': 'TXN560802', 'user_id': 1662, 'amount': 909.0, 'transaction_date': None}, {'transaction_id': 'TXN413098', 'user_id': 1642, 'amount': -4391.1, 'transaction_date': None})]
(Background on this error at: https://sqlalche.me/e/14/gkpj)
[2025-02-23T11:34:57.249+0000] {taskinstance.py:1206} INFO - Marking task as FAILED. dag_id=open_tax_etl, task_id=load_task, run_id=manual__2025-02-23T11:34:51.304291+00:00, execution_date=20250223T113451, start_date=20250223T113456, end_date=20250223T113457
[2025-02-23T11:34:57.259+0000] {standard_task_runner.py:110} ERROR - Failed to execute job 56 for task load_task ((psycopg2.errors.NotNullViolation) null value in column "transaction_date" of relation "transactions" violates not-null constraint
DETAIL:  Failing row contains (TXN749110, 1716, null, null).

[SQL: INSERT INTO transactions (transaction_id, user_id, amount, transaction_date) VALUES (%(transaction_id)s, %(user_id)s, %(amount)s, %(transaction_date)s)]
[parameters: ({'transaction_id': 'TXN204793', 'user_id': 1408, 'amount': 0.0, 'transaction_date': '2024-07-11'}, {'transaction_id': 'TXN749110', 'user_id': 1716, 'amount': None, 'transaction_date': None}, {'transaction_id': 'TXN984574', 'user_id': 1934, 'amount': None, 'transaction_date': None}, {'transaction_id': 'TXN180036', 'user_id': 1034, 'amount': -3437.55, 'transaction_date': None}, {'transaction_id': 'TXN147245', 'user_id': 1497, 'amount': 0.0, 'transaction_date': None}, {'transaction_id': 'TXN258146', 'user_id': 1616, 'amount': -1127.9, 'transaction_date': '2024-04-09'}, {'transaction_id': 'TXN372021', 'user_id': 1269, 'amount': 4990.0, 'transaction_date': None}, {'transaction_id': 'TXN205034', 'user_id': 1445, 'amount': 906.17, 'transaction_date': None}  ... displaying 10 of 1000 total bound parameter sets ...  {'transaction_id': 'TXN560802', 'user_id': 1662, 'amount': 909.0, 'transaction_date': None}, {'transaction_id': 'TXN413098', 'user_id': 1642, 'amount': -4391.1, 'transaction_date': None})]
(Background on this error at: https://sqlalche.me/e/14/gkpj); 2117)
[2025-02-23T11:34:57.303+0000] {local_task_job_runner.py:243} INFO - Task exited with return code 1
[2025-02-23T11:34:57.317+0000] {taskinstance.py:3503} INFO - 0 downstream tasks scheduled from follow-on schedule check
[2025-02-23T11:34:57.318+0000] {local_task_job_runner.py:222} INFO - ::endgroup::
